Workbook

Sheet Config
A1: CONFIGURATION
A2: Le point de depart : renseignez le dossier libs, puis lancez INIT.
A3: Affaire | B3: 2024_06_264 | D3: Client | E3: ALI
A4: Indice | B4: A | D4: Le | E4: 18/09/2026
B6: Dossier libs | C6: C:\Affaires\2024_06_264\libs | E6: LE SEUL CHAMP INDISPENSABLE. La macro INIT lit ce dossier, ouvre chaque .ddt et .dfb, et remplit l'onglet Catalogue. Tout le reste en decoule.
B7: Automate | C7: BMX P34 2020 | E7: la reference CPU, reprise sur l'onglet Cartes API
B8: Tache | C8: MAST | E8: la tache des sections generees
B9: Periode (ms) | C9: 20 | E9: sa periode : les blocs en tirent leurs temporisations
B10: Zone MW debut | C10: 1000 | E10: premiere adresse mot utilisable pour les reports
B11: Zone MW fin | C11: 1999 | E11: derniere
B12: Zone MX debut | C12: 0 | E12: premiere adresse bit
B13: Zone MX fin | C13: 511 | E13: derniere
B16: MARCHE A SUIVRE
B17: 1. INIT | C17: lit le dossier libs, remplit le Catalogue
B18: 2. Cartes API | C18: declarez vos cartes, les voies se creent
B19: 3. E/S | C19: double-clic sur une voie pour la regler
B20: 4. Ajouter equipement | C20: famille, voies, adresses de report
B21: 5. Tout recalculer | C21: reports, cartographie, ST
B23: Rien n'est obligatoire dans l'ordre : on peut declarer des voies sans equipement, un equipement sans report, un report sans voie. Les liens se font quand ils ont un sens.
B25: TABLEAU DE BORD | L25: Les chiffres sont des formules : ils ne peuvent pas etre perimes.
B26: Cartes declarees | C26: =COUNTIF('Cartes API'!$A$9:$A$48,"?*") -> 6 | L26: Tranche | M26: Occupes
B27: Voies declarees | C27: =COUNTIF(ES!$B$9:$B$608,"?*") -> 0 | L27: =IF(MW_Debut+0>MW_Fin,"",(MW_Debut+0)&"-"&MIN(MW_Debut+99,MW_Fin)) -> 1000-1099 | M27: =IF(MW_Debut+0>MW_Fin,"",SUMPRODUCT((Liens!$G$9:$G$808="MW")*(Liens!$H$9:$H$808>=MW_Debut+0)*(Liens!$H$9:$H$808<=MIN(MW_Debut+99,MW_Fin)))) -> 0
B28: dont entrees TOR | C28: =COUNTIF(ES!$A$9:$A$608,"DI") -> 0 | L28: =IF(MW_Debut+100>MW_Fin,"",(MW_Debut+100)&"-"&MIN(MW_Debut+199,MW_Fin)) -> 1100-1199 | M28: =IF(MW_Debut+100>MW_Fin,"",SUMPRODUCT((Liens!$G$9:$G$808="MW")*(Liens!$H$9:$H$808>=MW_Debut+100)*(Liens!$H$9:$H$808<=MIN(MW_Debut+199,MW_Fin)))) -> 0
B29: dont sorties TOR | C29: =COUNTIF(ES!$A$9:$A$608,"DO") -> 0 | L29: =IF(MW_Debut+200>MW_Fin,"",(MW_Debut+200)&"-"&MIN(MW_Debut+299,MW_Fin)) -> 1200-1299 | M29: =IF(MW_Debut+200>MW_Fin,"",SUMPRODUCT((Liens!$G$9:$G$808="MW")*(Liens!$H$9:$H$808>=MW_Debut+200)*(Liens!$H$9:$H$808<=MIN(MW_Debut+299,MW_Fin)))) -> 0
B30: dont entrees ANA | C30: =COUNTIF(ES!$A$9:$A$608,"AI") -> 0 | L30: =IF(MW_Debut+300>MW_Fin,"",(MW_Debut+300)&"-"&MIN(MW_Debut+399,MW_Fin)) -> 1300-1399 | M30: =IF(MW_Debut+300>MW_Fin,"",SUMPRODUCT((Liens!$G$9:$G$808="MW")*(Liens!$H$9:$H$808>=MW_Debut+300)*(Liens!$H$9:$H$808<=MIN(MW_Debut+399,MW_Fin)))) -> 0
B31: dont sorties ANA | C31: =COUNTIF(ES!$A$9:$A$608,"AO") -> 0 | L31: =IF(MW_Debut+400>MW_Fin,"",(MW_Debut+400)&"-"&MIN(MW_Debut+499,MW_Fin)) -> 1400-1499 | M31: =IF(MW_Debut+400>MW_Fin,"",SUMPRODUCT((Liens!$G$9:$G$808="MW")*(Liens!$H$9:$H$808>=MW_Debut+400)*(Liens!$H$9:$H$808<=MIN(MW_Debut+499,MW_Fin)))) -> 0
B32: Voies cablees | C32: =COUNTIF(Cablage!$A$9:$A$608,"?*") -> 0 | L32: =IF(MW_Debut+500>MW_Fin,"",(MW_Debut+500)&"-"&MIN(MW_Debut+599,MW_Fin)) -> 1500-1599 | M32: =IF(MW_Debut+500>MW_Fin,"",SUMPRODUCT((Liens!$G$9:$G$808="MW")*(Liens!$H$9:$H$808>=MW_Debut+500)*(Liens!$H$9:$H$808<=MIN(MW_Debut+599,MW_Fin)))) -> 0
B33: Voies libres | C33: =COUNTIF(ES!$B$9:$B$608,"?*")-COUNTIF(Cablage!$A$9:$A$608,"?*") -> 0 | L33: =IF(MW_Debut+600>MW_Fin,"",(MW_Debut+600)&"-"&MIN(MW_Debut+699,MW_Fin)) -> 1600-1699 | M33: =IF(MW_Debut+600>MW_Fin,"",SUMPRODUCT((Liens!$G$9:$G$808="MW")*(Liens!$H$9:$H$808>=MW_Debut+600)*(Liens!$H$9:$H$808<=MIN(MW_Debut+699,MW_Fin)))) -> 0
B34: Equipements | C34: =COUNTIF(Equipements!$A$9:$A$308,"?*") -> 0 | L34: =IF(MW_Debut+700>MW_Fin,"",(MW_Debut+700)&"-"&MIN(MW_Debut+799,MW_Fin)) -> 1700-1799 | M34: =IF(MW_Debut+700>MW_Fin,"",SUMPRODUCT((Liens!$G$9:$G$808="MW")*(Liens!$H$9:$H$808>=MW_Debut+700)*(Liens!$H$9:$H$808<=MIN(MW_Debut+799,MW_Fin)))) -> 0
B35: Reports | C35: =COUNTIF(Liens!$D$9:$D$808,"?*") -> 0 | L35: =IF(MW_Debut+800>MW_Fin,"",(MW_Debut+800)&"-"&MIN(MW_Debut+899,MW_Fin)) -> 1800-1899 | M35: =IF(MW_Debut+800>MW_Fin,"",SUMPRODUCT((Liens!$G$9:$G$808="MW")*(Liens!$H$9:$H$808>=MW_Debut+800)*(Liens!$H$9:$H$808<=MIN(MW_Debut+899,MW_Fin)))) -> 0
B36: informations (TM) | C36: =COUNTIF(Liens!$F$9:$F$808,"TM") -> 0 | L36: =IF(MW_Debut+900>MW_Fin,"",(MW_Debut+900)&"-"&MIN(MW_Debut+999,MW_Fin)) -> 1900-1999 | M36: =IF(MW_Debut+900>MW_Fin,"",SUMPRODUCT((Liens!$G$9:$G$808="MW")*(Liens!$H$9:$H$808>=MW_Debut+900)*(Liens!$H$9:$H$808<=MIN(MW_Debut+999,MW_Fin)))) -> 0
B37: alarmes (TA) | C37: =COUNTIF(Liens!$F$9:$F$808,"TA") -> 0 | L37: =IF(MW_Debut+1000>MW_Fin,"",(MW_Debut+1000)&"-"&MIN(MW_Debut+1099,MW_Fin)) | M37: =IF(MW_Debut+1000>MW_Fin,"",SUMPRODUCT((Liens!$G$9:$G$808="MW")*(Liens!$H$9:$H$808>=MW_Debut+1000)*(Liens!$H$9:$H$808<=MIN(MW_Debut+1099,MW_Fin))))
B38: commandes (TC) | C38: =COUNTIF(Liens!$F$9:$F$808,"TC") -> 0 | L38: =IF(MW_Debut+1100>MW_Fin,"",(MW_Debut+1100)&"-"&MIN(MW_Debut+1199,MW_Fin)) | M38: =IF(MW_Debut+1100>MW_Fin,"",SUMPRODUCT((Liens!$G$9:$G$808="MW")*(Liens!$H$9:$H$808>=MW_Debut+1100)*(Liens!$H$9:$H$808<=MIN(MW_Debut+1199,MW_Fin))))
B39: Mots %MW occupes | C39: =SUMPRODUCT((Liens!$G$9:$G$808="MW")*(Liens!$H$9:$H$808<>"")) -> 0 | L39: =IF(MW_Debut+1200>MW_Fin,"",(MW_Debut+1200)&"-"&MIN(MW_Debut+1299,MW_Fin)) | M39: =IF(MW_Debut+1200>MW_Fin,"",SUMPRODUCT((Liens!$G$9:$G$808="MW")*(Liens!$H$9:$H$808>=MW_Debut+1200)*(Liens!$H$9:$H$808<=MIN(MW_Debut+1299,MW_Fin))))
B40: Bits %MX occupes | C40: =SUMPRODUCT((Liens!$G$9:$G$808="MX")*(Liens!$H$9:$H$808<>"")) -> 0 | L40: =IF(MW_Debut+1300>MW_Fin,"",(MW_Debut+1300)&"-"&MIN(MW_Debut+1399,MW_Fin)) | M40: =IF(MW_Debut+1300>MW_Fin,"",SUMPRODUCT((Liens!$G$9:$G$808="MW")*(Liens!$H$9:$H$808>=MW_Debut+1300)*(Liens!$H$9:$H$808<=MIN(MW_Debut+1399,MW_Fin))))
B41: Conflits d'adresse | C41: =_ETAT!$B$6 -> 0 | L41: =IF(MW_Debut+1400>MW_Fin,"",(MW_Debut+1400)&"-"&MIN(MW_Debut+1499,MW_Fin)) | M41: =IF(MW_Debut+1400>MW_Fin,"",SUMPRODUCT((Liens!$G$9:$G$808="MW")*(Liens!$H$9:$H$808>=MW_Debut+1400)*(Liens!$H$9:$H$808<=MIN(MW_Debut+1499,MW_Fin))))
L42: =IF(MW_Debut+1500>MW_Fin,"",(MW_Debut+1500)&"-"&MIN(MW_Debut+1599,MW_Fin)) | M42: =IF(MW_Debut+1500>MW_Fin,"",SUMPRODUCT((Liens!$G$9:$G$808="MW")*(Liens!$H$9:$H$808>=MW_Debut+1500)*(Liens!$H$9:$H$808<=MIN(MW_Debut+1599,MW_Fin))))
L43: =IF(MW_Debut+1600>MW_Fin,"",(MW_Debut+1600)&"-"&MIN(MW_Debut+1699,MW_Fin)) | M43: =IF(MW_Debut+1600>MW_Fin,"",SUMPRODUCT((Liens!$G$9:$G$808="MW")*(Liens!$H$9:$H$808>=MW_Debut+1600)*(Liens!$H$9:$H$808<=MIN(MW_Debut+1699,MW_Fin))))
L44: =IF(MW_Debut+1700>MW_Fin,"",(MW_Debut+1700)&"-"&MIN(MW_Debut+1799,MW_Fin)) | M44: =IF(MW_Debut+1700>MW_Fin,"",SUMPRODUCT((Liens!$G$9:$G$808="MW")*(Liens!$H$9:$H$808>=MW_Debut+1700)*(Liens!$H$9:$H$808<=MIN(MW_Debut+1799,MW_Fin))))
L45: =IF(MW_Debut+1800>MW_Fin,"",(MW_Debut+1800)&"-"&MIN(MW_Debut+1899,MW_Fin)) | M45: =IF(MW_Debut+1800>MW_Fin,"",SUMPRODUCT((Liens!$G$9:$G$808="MW")*(Liens!$H$9:$H$808>=MW_Debut+1800)*(Liens!$H$9:$H$808<=MIN(MW_Debut+1899,MW_Fin))))
...

Sheet Cartes API
A1: CARTES DE L'AUTOMATE
A2: Declarez une carte, ses voies se creent dans l'onglet E/S. La vue du rack est en dessous du tableau.
A3: Affaire | B3: 2024_06_264 | D3: Client | E3: ALI
A4: Indice | B4: A | D4: Le | E4: 18/09/2026
A6: Carte | H6: Programme | J6: Calcule | P6: Documentation
A7: Nom | B7: Rack | C7: Module | D7: Famille | E7: Reference | F7: Voies | G7: Active | H7: Tableau | I7: Instance | J7: Prefixe | K7: Premiere | L7: Derniere | M7: Bloc | N7: Declarees | O7: Etat | P7: Commentaire
A8: libre | B8: 0..7 ▾ | C8: 0..15 | D8: ▾ liste | E8: DDI 1602 | F8: 1..64 | G8: O/N ▾ | H8: nom ST | I8: du DFB | M8: taille | N8: voies creees
A9: DI_R0S4 | B9: 0 | C9: 4 | D9: DI | E9: BMX DDI 1602 | F9: 16 | G9: O | H9: CarteDI_R0S4 | I9: IO_DI_R0S4 | J9: =IF(D9="","",IF(D9="DI","%I",IF(D9="DO","%Q",IF(D9="AI","%IW","%QW")))) -> %I | K9: =IF(OR(J9="",B9="",C9=""),"",J9&B9&"."&C9&".0") -> %I0.4.0 | L9: =IF(OR(J9="",F9=""),"",J9&B9&"."&C9&"."&(F9-1)) -> %I0.4.15 | M9: =IF(F9="","",IF(OR(D9="DI",D9="DO"),"DFB_IO_DIG","DFB_IO_ANA")&TEXT(IF(F9<=4,4,IF(F9<=8,8,IF(F9<=16,16,IF(F9<=32,32,IF(F9<=64,64,"?"))))),"00")) -> DFB_IO_DIG16 | N9: =IF(A9="","",COUNTIF(ES!$B:$B,A9)) -> 0 | O9: =IF(A9="","",IF(N9=0,"aucune voie",IF(N9<F9,"il en manque "&(F9-N9),IF(N9>F9,"TROP : "&(N9-F9),"complete")))) -> aucune voie
A10: DO_R0S5 | B10: 0 | C10: 5 | D10: DO | E10: BMX DRA 1605 | F10: 16 | G10: O | H10: CarteDO_R0S5 | I10: IO_DO_R0S5 | J10: =IF(D10="","",IF(D10="DI","%I",IF(D10="DO","%Q",IF(D10="AI","%IW","%QW")))) -> %Q | K10: =IF(OR(J10="",B10="",C10=""),"",J10&B10&"."&C10&".0") -> %Q0.5.0 | L10: =IF(OR(J10="",F10=""),"",J10&B10&"."&C10&"."&(F10-1)) -> %Q0.5.15 | M10: =IF(F10="","",IF(OR(D10="DI",D10="DO"),"DFB_IO_DIG","DFB_IO_ANA")&TEXT(IF(F10<=4,4,IF(F10<=8,8,IF(F10<=16,16,IF(F10<=32,32,IF(F10<=64,64,"?"))))),"00")) -> DFB_IO_DIG16 | N10: =IF(A10="","",COUNTIF(ES!$B:$B,A10)) -> 0 | O10: =IF(A10="","",IF(N10=0,"aucune voie",IF(N10<F10,"il en manque "&(F10-N10),IF(N10>F10,"TROP : "&(N10-F10),"complete")))) -> aucune voie
A11: DI_R0S7 | B11: 0 | C11: 7 | D11: DI | E11: BMX DDI 1602 | F11: 16 | G11: O | H11: CarteDI_R0S7 | I11: IO_DI_R0S7 | J11: =IF(D11="","",IF(D11="DI","%I",IF(D11="DO","%Q",IF(D11="AI","%IW","%QW")))) -> %I | K11: =IF(OR(J11="",B11="",C11=""),"",J11&B11&"."&C11&".0") -> %I0.7.0 | L11: =IF(OR(J11="",F11=""),"",J11&B11&"."&C11&"."&(F11-1)) -> %I0.7.15 | M11: =IF(F11="","",IF(OR(D11="DI",D11="DO"),"DFB_IO_DIG","DFB_IO_ANA")&TEXT(IF(F11<=4,4,IF(F11<=8,8,IF(F11<=16,16,IF(F11<=32,32,IF(F11<=64,64,"?"))))),"00")) -> DFB_IO_DIG16 | N11: =IF(A11="","",COUNTIF(ES!$B:$B,A11)) -> 0 | O11: =IF(A11="","",IF(N11=0,"aucune voie",IF(N11<F11,"il en manque "&(F11-N11),IF(N11>F11,"TROP : "&(N11-F11),"complete")))) -> aucune voie
A12: DO_R0S8 | B12: 0 | C12: 8 | D12: DO | E12: BMX DRA 1605 | F12: 16 | G12: O | H12: CarteDO_R0S8 | I12: IO_DO_R0S8 | J12: =IF(D12="","",IF(D12="DI","%I",IF(D12="DO","%Q",IF(D12="AI","%IW","%QW")))) -> %Q | K12: =IF(OR(J12="",B12="",C12=""),"",J12&B12&"."&C12&".0") -> %Q0.8.0 | L12: =IF(OR(J12="",F12=""),"",J12&B12&"."&C12&"."&(F12-1)) -> %Q0.8.15 | M12: =IF(F12="","",IF(OR(D12="DI",D12="DO"),"DFB_IO_DIG","DFB_IO_ANA")&TEXT(IF(F12<=4,4,IF(F12<=8,8,IF(F12<=16,16,IF(F12<=32,32,IF(F12<=64,64,"?"))))),"00")) -> DFB_IO_DIG16 | N12: =IF(A12="","",COUNTIF(ES!$B:$B,A12)) -> 0 | O12: =IF(A12="","",IF(N12=0,"aucune voie",IF(N12<F12,"il en manque "&(F12-N12),IF(N12>F12,"TROP : "&(N12-F12),"complete")))) -> aucune voie
A13: AI_R0S10 | B13: 0 | C13: 10 | D13: AI | E13: BMX AMI 0810 | F13: 8 | G13: O | H13: CarteAI_R0S10 | I13: IO_AI_R0S10 | J13: =IF(D13="","",IF(D13="DI","%I",IF(D13="DO","%Q",IF(D13="AI","%IW","%QW")))) -> %IW | K13: =IF(OR(J13="",B13="",C13=""),"",J13&B13&"."&C13&".0") -> %IW0.10.0 | L13: =IF(OR(J13="",F13=""),"",J13&B13&"."&C13&"."&(F13-1)) -> %IW0.10.7 | M13: =IF(F13="","",IF(OR(D13="DI",D13="DO"),"DFB_IO_DIG","DFB_IO_ANA")&TEXT(IF(F13<=4,4,IF(F13<=8,8,IF(F13<=16,16,IF(F13<=32,32,IF(F13<=64,64,"?"))))),"00")) -> DFB_IO_ANA08 | N13: =IF(A13="","",COUNTIF(ES!$B:$B,A13)) -> 0 | O13: =IF(A13="","",IF(N13=0,"aucune voie",IF(N13<F13,"il en manque "&(F13-N13),IF(N13>F13,"TROP : "&(N13-F13),"complete")))) -> aucune voie
A14: AI_R0S11 | B14: 0 | C14: 11 | D14: AI | E14: BMX AMI 0810 | F14: 8 | G14: O | H14: CarteAI_R0S11 | I14: IO_AI_R0S11 | J14: =IF(D14="","",IF(D14="DI","%I",IF(D14="DO","%Q",IF(D14="AI","%IW","%QW")))) -> %IW | K14: =IF(OR(J14="",B14="",C14=""),"",J14&B14&"."&C14&".0") -> %IW0.11.0 | L14: =IF(OR(J14="",F14=""),"",J14&B14&"."&C14&"."&(F14-1)) -> %IW0.11.7 | M14: =IF(F14="","",IF(OR(D14="DI",D14="DO"),"DFB_IO_DIG","DFB_IO_ANA")&TEXT(IF(F14<=4,4,IF(F14<=8,8,IF(F14<=16,16,IF(F14<=32,32,IF(F14<=64,64,"?"))))),"00")) -> DFB_IO_ANA08 | N14: =IF(A14="","",COUNTIF(ES!$B:$B,A14)) -> 0 | O14: =IF(A14="","",IF(N14=0,"aucune voie",IF(N14<F14,"il en manque "&(F14-N14),IF(N14>F14,"TROP : "&(N14-F14),"complete")))) -> aucune voie
J15: =IF(D15="","",IF(D15="DI","%I",IF(D15="DO","%Q",IF(D15="AI","%IW","%QW")))) | K15: =IF(OR(J15="",B15="",C15=""),"",J15&B15&"."&C15&".0") | L15: =IF(OR(J15="",F15=""),"",J15&B15&"."&C15&"."&(F15-1)) | M15: =IF(F15="","",IF(OR(D15="DI",D15="DO"),"DFB_IO_DIG","DFB_IO_ANA")&TEXT(IF(F15<=4,4,IF(F15<=8,8,IF(F15<=16,16,IF(F15<=32,32,IF(F15<=64,64,"?"))))),"00")) | N15: =IF(A15="","",COUNTIF(ES!$B:$B,A15)) | O15: =IF(A15="","",IF(N15=0,"aucune voie",IF(N15<F15,"il en manque "&(F15-N15),IF(N15>F15,"TROP : "&(N15-F15),"complete"))))
J16: =IF(D16="","",IF(D16="DI","%I",IF(D16="DO","%Q",IF(D16="AI","%IW","%QW")))) | K16: =IF(OR(J16="",B16="",C16=""),"",J16&B16&"."&C16&".0") | L16: =IF(OR(J16="",F16=""),"",J16&B16&"."&C16&"."&(F16-1)) | M16: =IF(F16="","",IF(OR(D16="DI",D16="DO"),"DFB_IO_DIG","DFB_IO_ANA")&TEXT(IF(F16<=4,4,IF(F16<=8,8,IF(F16<=16,16,IF(F16<=32,32,IF(F16<=64,64,"?"))))),"00")) | N16: =IF(A16="","",COUNTIF(ES!$B:$B,A16)) | O16: =IF(A16="","",IF(N16=0,"aucune voie",IF(N16<F16,"il en manque "&(F16-N16),IF(N16>F16,"TROP : "&(N16-F16),"complete"))))
J17: =IF(D17="","",IF(D17="DI","%I",IF(D17="DO","%Q",IF(D17="AI","%IW","%QW")))) | K17: =IF(OR(J17="",B17="",C17=""),"",J17&B17&"."&C17&".0") | L17: =IF(OR(J17="",F17=""),"",J17&B17&"."&C17&"."&(F17-1)) | M17: =IF(F17="","",IF(OR(D17="DI",D17="DO"),"DFB_IO_DIG","DFB_IO_ANA")&TEXT(IF(F17<=4,4,IF(F17<=8,8,IF(F17<=16,16,IF(F17<=32,32,IF(F17<=64,64,"?"))))),"00")) | N17: =IF(A17="","",COUNTIF(ES!$B:$B,A17)) | O17: =IF(A17="","",IF(N17=0,"aucune voie",IF(N17<F17,"il en manque "&(F17-N17),IF(N17>F17,"TROP : "&(N17-F17),"complete"))))
J18: =IF(D18="","",IF(D18="DI","%I",IF(D18="DO","%Q",IF(D18="AI","%IW","%QW")))) | K18: =IF(OR(J18="",B18="",C18=""),"",J18&B18&"."&C18&".0") | L18: =IF(OR(J18="",F18=""),"",J18&B18&"."&C18&"."&(F18-1)) | M18: =IF(F18="","",IF(OR(D18="DI",D18="DO"),"DFB_IO_DIG","DFB_IO_ANA")&TEXT(IF(F18<=4,4,IF(F18<=8,8,IF(F18<=16,16,IF(F18<=32,32,IF(F18<=64,64,"?"))))),"00")) | N18: =IF(A18="","",COUNTIF(ES!$B:$B,A18)) | O18: =IF(A18="","",IF(N18=0,"aucune voie",IF(N18<F18,"il en manque "&(F18-N18),IF(N18>F18,"TROP : "&(N18-F18),"complete"))))
J19: =IF(D19="","",IF(D19="DI","%I",IF(D19="DO","%Q",IF(D19="AI","%IW","%QW")))) | K19: =IF(OR(J19="",B19="",C19=""),"",J19&B19&"."&C19&".0") | L19: =IF(OR(J19="",F19=""),"",J19&B19&"."&C19&"."&(F19-1)) | M19: =IF(F19="","",IF(OR(D19="DI",D19="DO"),"DFB_IO_DIG","DFB_IO_ANA")&TEXT(IF(F19<=4,4,IF(F19<=8,8,IF(F19<=16,16,IF(F19<=32,32,IF(F19<=64,64,"?"))))),"00")) | N19: =IF(A19="","",COUNTIF(ES!$B:$B,A19)) | O19: =IF(A19="","",IF(N19=0,"aucune voie",IF(N19<F19,"il en manque "&(F19-N19),IF(N19>F19,"TROP : "&(N19-F19),"complete"))))
J20: =IF(D20="","",IF(D20="DI","%I",IF(D20="DO","%Q",IF(D20="AI","%IW","%QW")))) | K20: =IF(OR(J20="",B20="",C20=""),"",J20&B20&"."&C20&".0") | L20: =IF(OR(J20="",F20=""),"",J20&B20&"."&C20&"."&(F20-1)) | M20: =IF(F20="","",IF(OR(D20="DI",D20="DO"),"DFB_IO_DIG","DFB_IO_ANA")&TEXT(IF(F20<=4,4,IF(F20<=8,8,IF(F20<=16,16,IF(F20<=32,32,IF(F20<=64,64,"?"))))),"00")) | N20: =IF(A20="","",COUNTIF(ES!$B:$B,A20)) | O20: =IF(A20="","",IF(N20=0,"aucune voie",IF(N20<F20,"il en manque "&(F20-N20),IF(N20>F20,"TROP : "&(N20-F20),"complete"))))
J21: =IF(D21="","",IF(D21="DI","%I",IF(D21="DO","%Q",IF(D21="AI","%IW","%QW")))) | K21: =IF(OR(J21="",B21="",C21=""),"",J21&B21&"."&C21&".0") | L21: =IF(OR(J21="",F21=""),"",J21&B21&"."&C21&"."&(F21-1)) | M21: =IF(F21="","",IF(OR(D21="DI",D21="DO"),"DFB_IO_DIG","DFB_IO_ANA")&TEXT(IF(F21<=4,4,IF(F21<=8,8,IF(F21<=16,16,IF(F21<=32,32,IF(F21<=64,64,"?"))))),"00")) | N21: =IF(A21="","",COUNTIF(ES!$B:$B,A21)) | O21: =IF(A21="","",IF(N21=0,"aucune voie",IF(N21<F21,"il en manque "&(F21-N21),IF(N21>F21,"TROP : "&(N21-F21),"complete"))))
J22: =IF(D22="","",IF(D22="DI","%I",IF(D22="DO","%Q",IF(D22="AI","%IW","%QW")))) | K22: =IF(OR(J22="",B22="",C22=""),"",J22&B22&"."&C22&".0") | L22: =IF(OR(J22="",F22=""),"",J22&B22&"."&C22&"."&(F22-1)) | M22: =IF(F22="","",IF(OR(D22="DI",D22="DO"),"DFB_IO_DIG","DFB_IO_ANA")&TEXT(IF(F22<=4,4,IF(F22<=8,8,IF(F22<=16,16,IF(F22<=32,32,IF(F22<=64,64,"?"))))),"00")) | N22: =IF(A22="","",COUNTIF(ES!$B:$B,A22)) | O22: =IF(A22="","",IF(N22=0,"aucune voie",IF(N22<F22,"il en manque "&(F22-N22),IF(N22>F22,"TROP : "&(N22-F22),"complete"))))
J23: =IF(D23="","",IF(D23="DI","%I",IF(D23="DO","%Q",IF(D23="AI","%IW","%QW")))) | K23: =IF(OR(J23="",B23="",C23=""),"",J23&B23&"."&C23&".0") | L23: =IF(OR(J23="",F23=""),"",J23&B23&"."&C23&"."&(F23-1)) | M23: =IF(F23="","",IF(OR(D23="DI",D23="DO"),"DFB_IO_DIG","DFB_IO_ANA")&TEXT(IF(F23<=4,4,IF(F23<=8,8,IF(F23<=16,16,IF(F23<=32,32,IF(F23<=64,64,"?"))))),"00")) | N23: =IF(A23="","",COUNTIF(ES!$B:$B,A23)) | O23: =IF(A23="","",IF(N23=0,"aucune voie",IF(N23<F23,"il en manque "&(F23-N23),IF(N23>F23,"TROP : "&(N23-F23),"complete"))))
J24: =IF(D24="","",IF(D24="DI","%I",IF(D24="DO","%Q",IF(D24="AI","%IW","%QW")))) | K24: =IF(OR(J24="",B24="",C24=""),"",J24&B24&"."&C24&".0") | L24: =IF(OR(J24="",F24=""),"",J24&B24&"."&C24&"."&(F24-1)) | M24: =IF(F24="","",IF(OR(D24="DI",D24="DO"),"DFB_IO_DIG","DFB_IO_ANA")&TEXT(IF(F24<=4,4,IF(F24<=8,8,IF(F24<=16,16,IF(F24<=32,32,IF(F24<=64,64,"?"))))),"00")) | N24: =IF(A24="","",COUNTIF(ES!$B:$B,A24)) | O24: =IF(A24="","",IF(N24=0,"aucune voie",IF(N24<F24,"il en manque "&(F24-N24),IF(N24>F24,"TROP : "&(N24-F24),"complete"))))
J25: =IF(D25="","",IF(D25="DI","%I",IF(D25="DO","%Q",IF(D25="AI","%IW","%QW")))) | K25: =IF(OR(J25="",B25="",C25=""),"",J25&B25&"."&C25&".0") | L25: =IF(OR(J25="",F25=""),"",J25&B25&"."&C25&"."&(F25-1)) | M25: =IF(F25="","",IF(OR(D25="DI",D25="DO"),"DFB_IO_DIG","DFB_IO_ANA")&TEXT(IF(F25<=4,4,IF(F25<=8,8,IF(F25<=16,16,IF(F25<=32,32,IF(F25<=64,64,"?"))))),"00")) | N25: =IF(A25="","",COUNTIF(ES!$B:$B,A25)) | O25: =IF(A25="","",IF(N25=0,"aucune voie",IF(N25<F25,"il en manque "&(F25-N25),IF(N25>F25,"TROP : "&(N25-F25),"complete"))))
J26: =IF(D26="","",IF(D26="DI","%I",IF(D26="DO","%Q",IF(D26="AI","%IW","%QW")))) | K26: =IF(OR(J26="",B26="",C26=""),"",J26&B26&"."&C26&".0") | L26: =IF(OR(J26="",F26=""),"",J26&B26&"."&C26&"."&(F26-1)) | M26: =IF(F26="","",IF(OR(D26="DI",D26="DO"),"DFB_IO_DIG","DFB_IO_ANA")&TEXT(IF(F26<=4,4,IF(F26<=8,8,IF(F26<=16,16,IF(F26<=32,32,IF(F26<=64,64,"?"))))),"00")) | N26: =IF(A26="","",COUNTIF(ES!$B:$B,A26)) | O26: =IF(A26="","",IF(N26=0,"aucune voie",IF(N26<F26,"il en manque "&(F26-N26),IF(N26>F26,"TROP : "&(N26-F26),"complete"))))
... J48: =IF(D48="","",IF(D48="DI","%I",IF(D48="DO","%Q",IF(D48="AI","%IW","%QW")))) | K48: =IF(OR(J48="",B48="",C48=""),"",J48&B48&"."&C48&".0") | L48: =IF(OR(J48="",F48=""),"",J48&B48&"."&C48&"."&(F48-1)) | M48: =IF(F48="","",IF(OR(D48="DI",D48="DO"),"DFB_IO_DIG","DFB_IO_ANA")&TEXT(IF(F48<=4,4,IF(F48<=8,8,IF(F48<=16,16,IF(F48<=32,32,IF(F48<=64,64,"?"))))),"00")) | N48: =IF(A48="","",COUNTIF(ES!$B:$B,A48)) | O48: =IF(A48="","",IF(N48=0,"aucune voie",IF(N48<F48,"il en manque "&(F48-N48),IF(N48>F48,"TROP : "&(N48-F48),"complete"))))
BR50: Le bouton Creer les voies ajoute dans l'onglet E/S ce qui manque pour chaque carte active. Il n'efface jamais : une voie deja reglee reste telle quelle.
BR51: La colonne Etat compare les voies declarees ici et celles qui existent vraiment. "TROP" veut dire qu'il reste des voies d'une carte reduite.

Sheet Vue Rack
A1: VUE DES RACKS
A2: Une case par emplacement. Le bouton Rafraichir la vue la remplit depuis l'onglet Cartes API.
A3: Affaire | B3: 2024_06_264 | D3: Client | E3: ALI
A4: Indice | B4: A | D4: Le | E4: 18/09/2026
A9: Rack 0 | B9: 0 | C9: 1 | D9: 2 | E9: 3 | F9: 4 | G9: 5 | H9: 6 | I9: 7 | J9: 8 | K9: 9 | L9: 10 | M9: 11 | N9: 12 | O9: 13 | P9: 14 | Q9: 15
A10: nom
A11: famille
A12: reference
A13: voies
A14: etat
A16: Rack 1 | B16: 0 | C16: 1 | D16: 2 | E16: 3 | F16: 4 | G16: 5 | H16: 6 | I16: 7 | J16: 8 | K16: 9 | L16: 10 | M16: 11 | N16: 12 | O16: 13 | P16: 14 | Q16: 15
A17: nom
A18: famille
A19: reference
A20: voies
A21: etat
A23: Rack 2 | B23: 0 | C23: 1 | D23: 2 | E23: 3 | F23: 4 | G23: 5 | H23: 6 | I23: 7 | J23: 8 | K23: 9 | L23: 10 | M23: 11 | N23: 12 | O23: 13 | P23: 14 | Q23: 15
A24: nom
A25: famille
A26: reference
A27: voies
A28: etat
A30: Rack 3 | B30: 0 | C30: 1 | D30: 2 | E30: 3 | F30: 4 | G30: 5 | H30: 6 | I30: 7 | J30: 8 | K30: 9 | L30: 10 | M30: 11 | N30: 12 | O30: 13 | P30: 14 | Q30: 15
A31: nom
A32: famille
A33: reference
A34: voies
A35: etat
A37: Rack 4 | B37: 0 | C37: 1 | D37: 2 | E37: 3 | F37: 4 | G37: 5 | H37: 6 | I37: 7 | J37: 8 | K37: 9 | L37: 10 | M37: 11 | N37: 12 | O37: 13 | P37: 14 | Q37: 15
A38: nom
A39: famille
A40: reference
A41: voies
A42: etat
A44: Rack 5 | B44: 0 | C44: 1 | D44: 2 | E44: 3 | F44: 4 | G44: 5 | H44: 6 | I44: 7 | J44: 8 | K44: 9 | L44: 10 | M44: 11 | N44: 12 | O44: 13 | P44: 14 | Q44: 15
A45: nom
A46: famille
A47: reference
A48: voies
A49: etat
...

Sheet ES
A1: ENTREES / SORTIES
A2: Les quatre familles ensemble. Filtrez sur Famille pour n'en voir qu'une ; double-cliquez une ligne pour la regler.
A3: Affaire | B3: 2024_06_264 | D3: Client | E3: ALI
A4: Indice | B4: A | D4: Le | E4: 18/09/2026
A6: Voie | K6: Reglages TOR | Q6: Echelle ANA | Z6: Seuil 0 | AF6: Seuil 1 | AL6: Seuil 2 | AR6: Seuil 3 | AX6: Documentation
A7: Famille | B7: Carte | C7: Voie | D7: Designation | E7: Repere | F7: Adresse | G7: Tableau | H7: Index | I7: Acces ST | J7: Equipement | K7: Inv | L7: DebounceMs | M7: AlarmEn | N7: AlarmState | O7: AlarmDelayMs | P7: Sev | Q7: Unite | R7: RawMin | S7: RawMax | T7: EngMin | U7: EngMax | V7: Clamp | W7: DeadBand | X7: FiltN | Y7: RateMax | Z7: S0_En | AA7: S0_Dir | AB7: S0_Val | AC7: S0_Hyst | AD7: S0_DelayMs | AE7: S0_Sev | AF7: S1_En | AG7: S1_Dir | AH7: S1_Val | AI7: S1_Hyst | AJ7: S1_DelayMs | AK7: S1_Sev | AL7: S2_En | AM7: S2_Dir | AN7: S2_Val | AO7: S2_Hyst | AP7: S2_DelayMs | AQ7: S2_Sev | AR7: S3_En | AS7: S3_Dir | AT7: S3_Val | AU7: S3_Hyst | AV7: S3_DelayMs | AW7: S3_Sev | AX7: Commentaire
A8: DI/DO/AI/AO ▾ | B8: ▾ liste | C8: 0..63 | D8: ce que c'est | E8: schema | H8: dans le tableau | J8: lien | K8: O/N | L8: ms | M8: O/N | N8: 0/1 | O8: ms | P8: 1..4 | R8: pts | S8: pts | V8: O/N | X8: 0..8 | Y8: u/s | Z8: O/N | AA8: H/B | AD8: ms | AE8: 1..4 | AF8: O/N | AG8: H/B | AJ8: ms | AK8: 1..4 | AL8: O/N | AM8: H/B | AP8: ms | AQ8: 1..4 | AR8: O/N | AS8: H/B | AV8: ms | AW8: 1..4
F9: =IFERROR(IF(OR($B9="",$C9=""),"",INDEX('Cartes API'!$J:$J,MATCH($B9,'Cartes API'!$A:$A,0))&INDEX('Cartes API'!$B:$B,MATCH($B9,'Cartes API'!$A:$A,0))&"."&INDEX('Cartes API'!$C:$C,MATCH($B9,'Cartes API'!$A:$A,0))&"."&$C9),"") | G9: =IFERROR(IF($B9="","",INDEX('Cartes API'!$H:$H,MATCH($B9,'Cartes API'!$A:$A,0))),"") | I9: =IF(OR($G9="",$H9=""),"",$G9&"["&$H9&"]") | J9: =IFERROR(INDEX(Cablage!$A:$A,MATCH($I9,Cablage!$F:$F,0)),"")
F10: =IFERROR(IF(OR($B10="",$C10=""),"",INDEX('Cartes API'!$J:$J,MATCH($B10,'Cartes API'!$A:$A,0))&INDEX('Cartes API'!$B:$B,MATCH($B10,'Cartes API'!$A:$A,0))&"."&INDEX('Cartes API'!$C:$C,MATCH($B10,'Cartes API'!$A:$A,0))&"."&$C10),"") | G10: =IFERROR(IF($B10="","",INDEX('Cartes API'!$H:$H,MATCH($B10,'Cartes API'!$A:$A,0))),"") | I10: =IF(OR($G10="",$H10=""),"",$G10&"["&$H10&"]") | J10: =IFERROR(INDEX(Cablage!$A:$A,MATCH($I10,Cablage!$F:$F,0)),"")
F11: =IFERROR(IF(OR($B11="",$C11=""),"",INDEX('Cartes API'!$J:$J,MATCH($B11,'Cartes API'!$A:$A,0))&INDEX('Cartes API'!$B:$B,MATCH($B11,'Cartes API'!$A:$A,0))&"."&INDEX('Cartes API'!$C:$C,MATCH($B11,'Cartes API'!$A:$A,0))&"."&$C11),"") | G11: =IFERROR(IF($B11="","",INDEX('Cartes API'!$H:$H,MATCH($B11,'Cartes API'!$A:$A,0))),"") | I11: =IF(OR($G11="",$H11=""),"",$G11&"["&$H11&"]") | J11: =IFERROR(INDEX(Cablage!$A:$A,MATCH($I11,Cablage!$F:$F,0)),"")
F12: =IFERROR(IF(OR($B12="",$C12=""),"",INDEX('Cartes API'!$J:$J,MATCH($B12,'Cartes API'!$A:$A,0))&INDEX('Cartes API'!$B:$B,MATCH($B12,'Cartes API'!$A:$A,0))&"."&INDEX('Cartes API'!$C:$C,MATCH($B12,'Cartes API'!$A:$A,0))&"."&$C12),"") | G12: =IFERROR(IF($B12="","",INDEX('Cartes API'!$H:$H,MATCH($B12,'Cartes API'!$A:$A,0))),"") | I12: =IF(OR($G12="",$H12=""),"",$G12&"["&$H12&"]") | J12: =IFERROR(INDEX(Cablage!$A:$A,MATCH($I12,Cablage!$F:$F,0)),"")
F13: =IFERROR(IF(OR($B13="",$C13=""),"",INDEX('Cartes API'!$J:$J,MATCH($B13,'Cartes API'!$A:$A,0))&INDEX('Cartes API'!$B:$B,MATCH($B13,'Cartes API'!$A:$A,0))&"."&INDEX('Cartes API'!$C:$C,MATCH($B13,'Cartes API'!$A:$A,0))&"."&$C13),"") | G13: =IFERROR(IF($B13="","",INDEX('Cartes API'!$H:$H,MATCH($B13,'Cartes API'!$A:$A,0))),"") | I13: =IF(OR($G13="",$H13=""),"",$G13&"["&$H13&"]") | J13: =IFERROR(INDEX(Cablage!$A:$A,MATCH($I13,Cablage!$F:$F,0)),"")
F14: =IFERROR(IF(OR($B14="",$C14=""),"",INDEX('Cartes API'!$J:$J,MATCH($B14,'Cartes API'!$A:$A,0))&INDEX('Cartes API'!$B:$B,MATCH($B14,'Cartes API'!$A:$A,0))&"."&INDEX('Cartes API'!$C:$C,MATCH($B14,'Cartes API'!$A:$A,0))&"."&$C14),"") | G14: =IFERROR(IF($B14="","",INDEX('Cartes API'!$H:$H,MATCH($B14,'Cartes API'!$A:$A,0))),"") | I14: =IF(OR($G14="",$H14=""),"",$G14&"["&$H14&"]") | J14: =IFERROR(INDEX(Cablage!$A:$A,MATCH($I14,Cablage!$F:$F,0)),"")
F15: =IFERROR(IF(OR($B15="",$C15=""),"",INDEX('Cartes API'!$J:$J,MATCH($B15,'Cartes API'!$A:$A,0))&INDEX('Cartes API'!$B:$B,MATCH($B15,'Cartes API'!$A:$A,0))&"."&INDEX('Cartes API'!$C:$C,MATCH($B15,'Cartes API'!$A:$A,0))&"."&$C15),"") | G15: =IFERROR(IF($B15="","",INDEX('Cartes API'!$H:$H,MATCH($B15,'Cartes API'!$A:$A,0))),"") | I15: =IF(OR($G15="",$H15=""),"",$G15&"["&$H15&"]") | J15: =IFERROR(INDEX(Cablage!$A:$A,MATCH($I15,Cablage!$F:$F,0)),"")
F16: =IFERROR(IF(OR($B16="",$C16=""),"",INDEX('Cartes API'!$J:$J,MATCH($B16,'Cartes API'!$A:$A,0))&INDEX('Cartes API'!$B:$B,MATCH($B16,'Cartes API'!$A:$A,0))&"."&INDEX('Cartes API'!$C:$C,MATCH($B16,'Cartes API'!$A:$A,0))&"."&$C16),"") | G16: =IFERROR(IF($B16="","",INDEX('Cartes API'!$H:$H,MATCH($B16,'Cartes API'!$A:$A,0))),"") | I16: =IF(OR($G16="",$H16=""),"",$G16&"["&$H16&"]") | J16: =IFERROR(INDEX(Cablage!$A:$A,MATCH($I16,Cablage!$F:$F,0)),"")
F17: =IFERROR(IF(OR($B17="",$C17=""),"",INDEX('Cartes API'!$J:$J,MATCH($B17,'Cartes API'!$A:$A,0))&INDEX('Cartes API'!$B:$B,MATCH($B17,'Cartes API'!$A:$A,0))&"."&INDEX('Cartes API'!$C:$C,MATCH($B17,'Cartes API'!$A:$A,0))&"."&$C17),"") | G17: =IFERROR(IF($B17="","",INDEX('Cartes API'!$H:$H,MATCH($B17,'Cartes API'!$A:$A,0))),"") | I17: =IF(OR($G17="",$H17=""),"",$G17&"["&$H17&"]") | J17: =IFERROR(INDEX(Cablage!$A:$A,MATCH($I17,Cablage!$F:$F,0)),"")
F18: =IFERROR(IF(OR($B18="",$C18=""),"",INDEX('Cartes API'!$J:$J,MATCH($B18,'Cartes API'!$A:$A,0))&INDEX('Cartes API'!$B:$B,MATCH($B18,'Cartes API'!$A:$A,0))&"."&INDEX('Cartes API'!$C:$C,MATCH($B18,'Cartes API'!$A:$A,0))&"."&$C18),"") | G18: =IFERROR(IF($B18="","",INDEX('Cartes API'!$H:$H,MATCH($B18,'Cartes API'!$A:$A,0))),"") | I18: =IF(OR($G18="",$H18=""),"",$G18&"["&$H18&"]") | J18: =IFERROR(INDEX(Cablage!$A:$A,MATCH($I18,Cablage!$F:$F,0)),"")
F19: =IFERROR(IF(OR($B19="",$C19=""),"",INDEX('Cartes API'!$J:$J,MATCH($B19,'Cartes API'!$A:$A,0))&INDEX('Cartes API'!$B:$B,MATCH($B19,'Cartes API'!$A:$A,0))&"."&INDEX('Cartes API'!$C:$C,MATCH($B19,'Cartes API'!$A:$A,0))&"."&$C19),"") | G19: =IFERROR(IF($B19="","",INDEX('Cartes API'!$H:$H,MATCH($B19,'Cartes API'!$A:$A,0))),"") | I19: =IF(OR($G19="",$H19=""),"",$G19&"["&$H19&"]") | J19: =IFERROR(INDEX(Cablage!$A:$A,MATCH($I19,Cablage!$F:$F,0)),"")
F20: =IFERROR(IF(OR($B20="",$C20=""),"",INDEX('Cartes API'!$J:$J,MATCH($B20,'Cartes API'!$A:$A,0))&INDEX('Cartes API'!$B:$B,MATCH($B20,'Cartes API'!$A:$A,0))&"."&INDEX('Cartes API'!$C:$C,MATCH($B20,'Cartes API'!$A:$A,0))&"."&$C20),"") | G20: =IFERROR(IF($B20="","",INDEX('Cartes API'!$H:$H,MATCH($B20,'Cartes API'!$A:$A,0))),"") | I20: =IF(OR($G20="",$H20=""),"",$G20&"["&$H20&"]") | J20: =IFERROR(INDEX(Cablage!$A:$A,MATCH($I20,Cablage!$F:$F,0)),"")
... F608: =IFERROR(IF(OR($B608="",$C608=""),"",INDEX('Cartes API'!$J:$J,MATCH($B608,'Cartes API'!$A:$A,0))&INDEX('Cartes API'!$B:$B,MATCH($B608,'Cartes API'!$A:$A,0))&"."&INDEX('Cartes API'!$C:$C,MATCH($B608,'Cartes API'!$A:$A,0))&"."&$C608),"") | G608: =IFERROR(IF($B608="","",INDEX('Cartes API'!$H:$H,MATCH($B608,'Cartes API'!$A:$A,0))),"") | I608: =IF(OR($G608="",$H608=""),"",$G608&"["&$H608&"]") | J608: =IFERROR(INDEX(Cablage!$A:$A,MATCH($I608,Cablage!$F:$F,0)),"")
BR610: Une couleur par famille dans la colonne A : les quatre parties se voient sans avoir a filtrer, et le filtre les separe quand on veut travailler sur une seule.
BR611: Les blocs Reglages TOR, Echelle ANA et Seuils sont replies : ouvrez avec le + en haut celui dont vous avez besoin. Une voie TOR laisse les colonnes ANA vides, et reciproquement.
BR612: La colonne Equipement se remplit toute seule quand une voie est cablee depuis l'assistant d'equipement. Elle reste vide si la voie ne sert a rien d'autre qu'a etre lue - ce qui est parfaitement admis.

Sheet Catalogue
A1: CATALOGUE DES DDT ET DFB
A2: Ecrit par INIT depuis le dossier libs. Seules les trois colonnes vertes sont a vous - et INIT ne les ecrase jamais.
A3: Affaire | B3: 2024_06_264 | D3: Client | E3: ALI | G3: D'OU CA VIENT : INIT parcourt libs\ et ses sous-dossiers, ouvre chaque .ddt et .dfb - ce sont des fichiers texte - et ecrit ici une ligne par parametre.
A4: Indice | B4: A | D4: Le | E4: 18/09/2026
A6: Origine | D6: Parametre | H6: Choix | K6: Documentation
A7: Famille | B7: Genre | C7: Fichier | D7: Nom | E7: Type | F7: Portee | G7: Defaut | H7: Reportable | I7: Type report | J7: Cablage E/S | K7: Commentaire
A8: DDT ou DFB | B8: ddt/dfb | C8: dans libs | H8: O/N ▾ | I8: TM/TA/TC ▾ | J8: DI/DO/AI/AO ▾
BR910: Reportable dit si ce parametre merite de remonter a l'IHM. Type report dit comment : TM information, TA alarme, TC commande.
BR911: Cablage E/S dit si ce parametre se branche sur une voie physique, et dans quel sens. Vide veut dire qu'il n'en vient pas : un defaut calcule par le bloc, une consigne qui vient de l'IHM.

Sheet Equipements
A1: EQUIPEMENTS
A2: Double-cliquez une ligne pour rouvrir l'assistant et changer ses voies ou ses adresses.
A3: Affaire | B3: 2024_06_264 | D3: Client | E3: ALI
A4: Indice | B4: A | D4: Le | E4: 18/09/2026
A6: Identification | E6: Programme | J6: Bilan | M6: Documentation
A7: Nom | B7: Famille | C7: Repere | D7: Actif | E7: Forme | F7: Variable | G7: Index | H7: Instance | I7: Acces ST | J7: Voies | K7: Reports | L7: Conflit | M7: Commentaire
A8: libre | B8: ▾ liste | C8: P1 | D8: O/N ▾ | E8: ▾ liste | F8: nom ST | G8: si tableau | H8: du DFB | J8: cablees | L8: index pris
I9: =IF(F9="","",IF(OR(E9="Variable seule",G9=""),F9,F9&"["&G9&"]")) | J9: =IF(A9="","",COUNTIF(Cablage!$A:$A,A9)) | K9: =IF(A9="","",COUNTIF(Liens!$A:$A,A9)) | L9: =IF(OR(A9="",E9="Variable seule",F9="",G9=""),"",IF(COUNTIFS($F$9:$F$308,F9,$G$9:$G$308,G9,$A$9:$A$308,"<>"&A9)>0,"index deja pris",""))
I10: =IF(F10="","",IF(OR(E10="Variable seule",G10=""),F10,F10&"["&G10&"]")) | J10: =IF(A10="","",COUNTIF(Cablage!$A:$A,A10)) | K10: =IF(A10="","",COUNTIF(Liens!$A:$A,A10)) | L10: =IF(OR(A10="",E10="Variable seule",F10="",G10=""),"",IF(COUNTIFS($F$9:$F$308,F10,$G$9:$G$308,G10,$A$9:$A$308,"<>"&A10)>0,"index deja pris",""))
I11: =IF(F11="","",IF(OR(E11="Variable seule",G11=""),F11,F11&"["&G11&"]")) | J11: =IF(A11="","",COUNTIF(Cablage!$A:$A,A11)) | K11: =IF(A11="","",COUNTIF(Liens!$A:$A,A11)) | L11: =IF(OR(A11="",E11="Variable seule",F11="",G11=""),"",IF(COUNTIFS($F$9:$F$308,F11,$G$9:$G$308,G11,$A$9:$A$308,"<>"&A11)>0,"index deja pris",""))
I12: =IF(F12="","",IF(OR(E12="Variable seule",G12=""),F12,F12&"["&G12&"]")) | J12: =IF(A12="","",COUNTIF(Cablage!$A:$A,A12)) | K12: =IF(A12="","",COUNTIF(Liens!$A:$A,A12)) | L12: =IF(OR(A12="",E12="Variable seule",F12="",G12=""),"",IF(COUNTIFS($F$9:$F$308,F12,$G$9:$G$308,G12,$A$9:$A$308,"<>"&A12)>0,"index deja pris",""))
I13: =IF(F13="","",IF(OR(E13="Variable seule",G13=""),F13,F13&"["&G13&"]")) | J13: =IF(A13="","",COUNTIF(Cablage!$A:$A,A13)) | K13: =IF(A13="","",COUNTIF(Liens!$A:$A,A13)) | L13: =IF(OR(A13="",E13="Variable seule",F13="",G13=""),"",IF(COUNTIFS($F$9:$F$308,F13,$G$9:$G$308,G13,$A$9:$A$308,"<>"&A13)>0,"index deja pris",""))
I14: =IF(F14="","",IF(OR(E14="Variable seule",G14=""),F14,F14&"["&G14&"]")) | J14: =IF(A14="","",COUNTIF(Cablage!$A:$A,A14)) | K14: =IF(A14="","",COUNTIF(Liens!$A:$A,A14)) | L14: =IF(OR(A14="",E14="Variable seule",F14="",G14=""),"",IF(COUNTIFS($F$9:$F$308,F14,$G$9:$G$308,G14,$A$9:$A$308,"<>"&A14)>0,"index deja pris",""))
I15: =IF(F15="","",IF(OR(E15="Variable seule",G15=""),F15,F15&"["&G15&"]")) | J15: =IF(A15="","",COUNTIF(Cablage!$A:$A,A15)) | K15: =IF(A15="","",COUNTIF(Liens!$A:$A,A15)) | L15: =IF(OR(A15="",E15="Variable seule",F15="",G15=""),"",IF(COUNTIFS($F$9:$F$308,F15,$G$9:$G$308,G15,$A$9:$A$308,"<>"&A15)>0,"index deja pris",""))
I16: =IF(F16="","",IF(OR(E16="Variable seule",G16=""),F16,F16&"["&G16&"]")) | J16: =IF(A16="","",COUNTIF(Cablage!$A:$A,A16)) | K16: =IF(A16="","",COUNTIF(Liens!$A:$A,A16)) | L16: =IF(OR(A16="",E16="Variable seule",F16="",G16=""),"",IF(COUNTIFS($F$9:$F$308,F16,$G$9:$G$308,G16,$A$9:$A$308,"<>"&A16)>0,"index deja pris",""))
I17: =IF(F17="","",IF(OR(E17="Variable seule",G17=""),F17,F17&"["&G17&"]")) | J17: =IF(A17="","",COUNTIF(Cablage!$A:$A,A17)) | K17: =IF(A17="","",COUNTIF(Liens!$A:$A,A17)) | L17: =IF(OR(A17="",E17="Variable seule",F17="",G17=""),"",IF(COUNTIFS($F$9:$F$308,F17,$G$9:$G$308,G17,$A$9:$A$308,"<>"&A17)>0,"index deja pris",""))
I18: =IF(F18="","",IF(OR(E18="Variable seule",G18=""),F18,F18&"["&G18&"]")) | J18: =IF(A18="","",COUNTIF(Cablage!$A:$A,A18)) | K18: =IF(A18="","",COUNTIF(Liens!$A:$A,A18)) | L18: =IF(OR(A18="",E18="Variable seule",F18="",G18=""),"",IF(COUNTIFS($F$9:$F$308,F18,$G$9:$G$308,G18,$A$9:$A$308,"<>"&A18)>0,"index deja pris",""))
I19: =IF(F19="","",IF(OR(E19="Variable seule",G19=""),F19,F19&"["&G19&"]")) | J19: =IF(A19="","",COUNTIF(Cablage!$A:$A,A19)) | K19: =IF(A19="","",COUNTIF(Liens!$A:$A,A19)) | L19: =IF(OR(A19="",E19="Variable seule",F19="",G19=""),"",IF(COUNTIFS($F$9:$F$308,F19,$G$9:$G$308,G19,$A$9:$A$308,"<>"&A19)>0,"index deja pris",""))
I20: =IF(F20="","",IF(OR(E20="Variable seule",G20=""),F20,F20&"["&G20&"]")) | J20: =IF(A20="","",COUNTIF(Cablage!$A:$A,A20)) | K20: =IF(A20="","",COUNTIF(Liens!$A:$A,A20)) | L20: =IF(OR(A20="",E20="Variable seule",F20="",G20=""),"",IF(COUNTIFS($F$9:$F$308,F20,$G$9:$G$308,G20,$A$9:$A$308,"<>"&A20)>0,"index deja pris",""))
... I308: =IF(F308="","",IF(OR(E308="Variable seule",G308=""),F308,F308&"["&G308&"]")) | J308: =IF(A308="","",COUNTIF(Cablage!$A:$A,A308)) | K308: =IF(A308="","",COUNTIF(Liens!$A:$A,A308)) | L308: =IF(OR(A308="",E308="Variable seule",F308="",G308=""),"",IF(COUNTIFS($F$9:$F$308,F308,$G$9:$G$308,G308,$A$9:$A$308,"<>"&A308)>0,"index deja pris",""))
BR310: Les deux colonnes de bilan comptent ce qui est reellement cable et reporte. Un equipement a zero des deux n'est pas une erreur : c'est un equipement declare dont on n'a pas encore decide.

Sheet Cablage
A1: CABLAGE DES ENTREES / SORTIES
A2: Ce que chaque voie alimente. Ecrit par l'assistant ; une ligne se retire avec le bouton Enlever le lien.
A3: Affaire | B3: 2024_06_264 | D3: Client | E3: ALI
A4: Indice | B4: A | D4: Le | E4: 18/09/2026
A6: Equipement | D6: Voie
A7: Equipement | B7: Parametre | C7: Cible | D7: Sens | E7: Ligne ES | F7: Acces voie | G7: Attribut | H7: Source | I7: Adresse | J7: Designation
D8: DI/DO/AI/AO
C9: =IFERROR(IF(OR(A9="",B9=""),"",INDEX(Equipements!$H:$H,MATCH(A9,Equipements!$A:$A,0))&"."&B9),"")
C10: =IFERROR(IF(OR(A10="",B10=""),"",INDEX(Equipements!$H:$H,MATCH(A10,Equipements!$A:$A,0))&"."&B10),"")
C11: =IFERROR(IF(OR(A11="",B11=""),"",INDEX(Equipements!$H:$H,MATCH(A11,Equipements!$A:$A,0))&"."&B11),"")
C12: =IFERROR(IF(OR(A12="",B12=""),"",INDEX(Equipements!$H:$H,MATCH(A12,Equipements!$A:$A,0))&"."&B12),"")
C13: =IFERROR(IF(OR(A13="",B13=""),"",INDEX(Equipements!$H:$H,MATCH(A13,Equipements!$A:$A,0))&"."&B13),"")
C14: =IFERROR(IF(OR(A14="",B14=""),"",INDEX(Equipements!$H:$H,MATCH(A14,Equipements!$A:$A,0))&"."&B14),"")
C15: =IFERROR(IF(OR(A15="",B15=""),"",INDEX(Equipements!$H:$H,MATCH(A15,Equipements!$A:$A,0))&"."&B15),"")
C16: =IFERROR(IF(OR(A16="",B16=""),"",INDEX(Equipements!$H:$H,MATCH(A16,Equipements!$A:$A,0))&"."&B16),"")
C17: =IFERROR(IF(OR(A17="",B17=""),"",INDEX(Equipements!$H:$H,MATCH(A17,Equipements!$A:$A,0))&"."&B17),"")
C18: =IFERROR(IF(OR(A18="",B18=""),"",INDEX(Equipements!$H:$H,MATCH(A18,Equipements!$A:$A,0))&"."&B18),"")
C19: =IFERROR(IF(OR(A19="",B19=""),"",INDEX(Equipements!$H:$H,MATCH(A19,Equipements!$A:$A,0))&"."&B19),"")
C20: =IFERROR(IF(OR(A20="",B20=""),"",INDEX(Equipements!$H:$H,MATCH(A20,Equipements!$A:$A,0))&"."&B20),"")
... C608: =IFERROR(IF(OR(A608="",B608=""),"",INDEX(Equipements!$H:$H,MATCH(A608,Equipements!$A:$A,0))&"."&B608),"")
BR610: Le cablage n'est PAS un report : une voie peut alimenter un equipement sans jamais remonter a l'IHM, et un report peut porter sur une valeur calculee qui ne vient d'aucune voie.

Sheet Liens
A1: REPORTS VERS L'IHM
A2: Une ligne par report. Les trois onglets de reports en sont derives : une adresse s'ecrit ici et nulle part ailleurs.
A3: Affaire | B3: 2024_06_264 | D3: Client | E3: ALI
A4: Indice | B4: A | D4: Le | E4: 18/09/2026
A6: Source | D6: Report | G6: Adresse | K6: Echelle | O6: Controle | P6: Documentation
A7: Equipement | B7: Parametre | C7: Chemin | D7: Designation | E7: Sens | F7: Type | G7: Zone | H7: Numero | I7: Bit | J7: Adr API | K7: Unite | L7: Mini | M7: Maxi | N7: Resolution | O7: Occupation | P7: Commentaire
A8: ▾ liste | B8: ▾ liste | D8: ce que l'operateur lit | E8: R/W ▾ | F8: TM/TA/TC ▾ | G8: MW/MX ▾ | I8: 0..15
C9: =IFERROR(IF(OR(A9="",B9=""),"",INDEX(Equipements!$H:$H,MATCH(A9,Equipements!$A:$A,0))&"."&B9),"") | J9: =IF(OR(G9="",H9=""),"","%"&G9&H9) | O9: =IF(H9="","",IF(I9="","mot entier","bit "&I9))
C10: =IFERROR(IF(OR(A10="",B10=""),"",INDEX(Equipements!$H:$H,MATCH(A10,Equipements!$A:$A,0))&"."&B10),"") | J10: =IF(OR(G10="",H10=""),"","%"&G10&H10) | O10: =IF(H10="","",IF(I10="","mot entier","bit "&I10))
C11: =IFERROR(IF(OR(A11="",B11=""),"",INDEX(Equipements!$H:$H,MATCH(A11,Equipements!$A:$A,0))&"."&B11),"") | J11: =IF(OR(G11="",H11=""),"","%"&G11&H11) | O11: =IF(H11="","",IF(I11="","mot entier","bit "&I11))
C12: =IFERROR(IF(OR(A12="",B12=""),"",INDEX(Equipements!$H:$H,MATCH(A12,Equipements!$A:$A,0))&"."&B12),"") | J12: =IF(OR(G12="",H12=""),"","%"&G12&H12) | O12: =IF(H12="","",IF(I12="","mot entier","bit "&I12))
C13: =IFERROR(IF(OR(A13="",B13=""),"",INDEX(Equipements!$H:$H,MATCH(A13,Equipements!$A:$A,0))&"."&B13),"") | J13: =IF(OR(G13="",H13=""),"","%"&G13&H13) | O13: =IF(H13="","",IF(I13="","mot entier","bit "&I13))
C14: =IFERROR(IF(OR(A14="",B14=""),"",INDEX(Equipements!$H:$H,MATCH(A14,Equipements!$A:$A,0))&"."&B14),"") | J14: =IF(OR(G14="",H14=""),"","%"&G14&H14) | O14: =IF(H14="","",IF(I14="","mot entier","bit "&I14))
C15: =IFERROR(IF(OR(A15="",B15=""),"",INDEX(Equipements!$H:$H,MATCH(A15,Equipements!$A:$A,0))&"."&B15),"") | J15: =IF(OR(G15="",H15=""),"","%"&G15&H15) | O15: =IF(H15="","",IF(I15="","mot entier","bit "&I15))
C16: =IFERROR(IF(OR(A16="",B16=""),"",INDEX(Equipements!$H:$H,MATCH(A16,Equipements!$A:$A,0))&"."&B16),"") | J16: =IF(OR(G16="",H16=""),"","%"&G16&H16) | O16: =IF(H16="","",IF(I16="","mot entier","bit "&I16))
C17: =IFERROR(IF(OR(A17="",B17=""),"",INDEX(Equipements!$H:$H,MATCH(A17,Equipements!$A:$A,0))&"."&B17),"") | J17: =IF(OR(G17="",H17=""),"","%"&G17&H17) | O17: =IF(H17="","",IF(I17="","mot entier","bit "&I17))
C18: =IFERROR(IF(OR(A18="",B18=""),"",INDEX(Equipements!$H:$H,MATCH(A18,Equipements!$A:$A,0))&"."&B18),"") | J18: =IF(OR(G18="",H18=""),"","%"&G18&H18) | O18: =IF(H18="","",IF(I18="","mot entier","bit "&I18))
C19: =IFERROR(IF(OR(A19="",B19=""),"",INDEX(Equipements!$H:$H,MATCH(A19,Equipements!$A:$A,0))&"."&B19),"") | J19: =IF(OR(G19="",H19=""),"","%"&G19&H19) | O19: =IF(H19="","",IF(I19="","mot entier","bit "&I19))
C20: =IFERROR(IF(OR(A20="",B20=""),"",INDEX(Equipements!$H:$H,MATCH(A20,Equipements!$A:$A,0))&"."&B20),"") | J20: =IF(OR(G20="",H20=""),"","%"&G20&H20) | O20: =IF(H20="","",IF(I20="","mot entier","bit "&I20))
... C808: =IFERROR(IF(OR(A808="",B808=""),"",INDEX(Equipements!$H:$H,MATCH(A808,Equipements!$A:$A,0))&"."&B808),"") | J808: =IF(OR(G808="",H808=""),"","%"&G808&H808) | O808: =IF(H808="","",IF(I808="","mot entier","bit "&I808))
BR810: Le tri entre les trois onglets de reports se fait tout seul : %MX en tout-ou-rien, %MW avec un bit en bits de mots, %MW seul en analogique.

Sheet Indices
A1: INDICES ET JOURNAL
A2: Le haut se remplit a la main. Le bas s'ecrit tout seul.
A3: Affaire | B3: 2024_06_264 | D3: Client | E3: ALI
A4: Indice | B4: A | D4: Le | E4: 18/09/2026
A6: Indice
A7: Indice | B7: Date | C7: Par | D7: Objet de la modification
A8: A, B, C...
A9: A | B9: 18/09/2026 | D9: creation du classeur
BR50: Le journal est ecrit par les macros : ajout et suppression d'equipement, attribution d'adresses, recalcul. Il ne se saisit pas.
A51: JOURNAL DES OPERATIONS
A52: Quand | B52: Quoi | C52: Detail | D52: Par

Sheet Reports TOR
A1: REPORTS - TOUT OU RIEN (%MX)
A2: Onglet DERIVE de la feuille Liens : ne rien saisir ici.
A3: Affaire | B3: 2024_06_264 | D3: Client | E3: ALI
A4: Indice | B4: A | D4: Le | E4: 18/09/2026
B6: Adr API | E6: Type | H6: Conformite API | J6: Conformite IHM
A7: Designation | B7: Adr API | C7: Mode | D7: Reset | E7: TM | F7: TA | G7: TC | H7: Animation | I7: Adressage | J7: Animation | K7: Alarme | L7: Commentaire
B8: IHM
BR410: Le bouton Tout recalculer le remplit depuis la feuille Liens.

Sheet Reports bits
A1: REPORTS - BITS DE MOTS (%MW)
A2: Onglet DERIVE de la feuille Liens : ne rien saisir ici.
A3: Affaire | B3: 2024_06_264 | D3: Client | E3: ALI
A4: Indice | B4: A | D4: Le | E4: 18/09/2026
B6: Adr API | D6: Type | H6: Conformite API | J6: Conformite IHM
A7: Designation | B7: MW | C7: MX | D7: TM | E7: TA | F7: TC | G7: RTN | H7: Animation | I7: Adressage | J7: Animation | K7: Alarme | L7: Commentaire
C8: bit
BR610: Le bouton Tout recalculer le remplit depuis la feuille Liens.

Sheet Reports ANA
A1: REPORTS - ANALOGIQUE (%MW)
A2: Onglet DERIVE de la feuille Liens : ne rien saisir ici.
A3: Affaire | B3: 2024_06_264 | D3: Client | E3: ALI
A4: Indice | B4: A | D4: Le | E4: 18/09/2026
B6: Adr API | C6: Type | E6: Echelle | I6: Conformite API | K6: Conformite IHM
A7: Designation | B7: Adr API | C7: TM | D7: TC | E7: Unite | F7: mini | G7: maxi | H7: resolution | I7: Animation | J7: Adressage | K7: Animation | L7: Commentaire
B8: IHM
BR410: Le bouton Tout recalculer le remplit depuis la feuille Liens.

Sheet Memoire MW
A1: CARTOGRAPHIE MEMOIRE %MW
A2: Une case par adresse, a partir de la plage declaree dans Config. Bleu : mot entier. Vert : des bits. Rouge : conflit.
A3: Affaire | B3: 2024_06_264 | D3: Client | E3: ALI
A4: Indice | B4: A | D4: Le | E4: 18/09/2026
A9: =IF(MW_Debut+0>MW_Fin,"","%MW"&(MW_Debut+0)) -> %MW1000
A10: =IF(MW_Debut+64>MW_Fin,"","%MW"&(MW_Debut+64)) -> %MW1064
A11: =IF(MW_Debut+128>MW_Fin,"","%MW"&(MW_Debut+128)) -> %MW1128
A12: =IF(MW_Debut+192>MW_Fin,"","%MW"&(MW_Debut+192)) -> %MW1192
A13: =IF(MW_Debut+256>MW_Fin,"","%MW"&(MW_Debut+256)) -> %MW1256
A14: =IF(MW_Debut+320>MW_Fin,"","%MW"&(MW_Debut+320)) -> %MW1320
A15: =IF(MW_Debut+384>MW_Fin,"","%MW"&(MW_Debut+384)) -> %MW1384
A16: =IF(MW_Debut+448>MW_Fin,"","%MW"&(MW_Debut+448)) -> %MW1448
A17: =IF(MW_Debut+512>MW_Fin,"","%MW"&(MW_Debut+512)) -> %MW1512
A18: =IF(MW_Debut+576>MW_Fin,"","%MW"&(MW_Debut+576)) -> %MW1576
A19: =IF(MW_Debut+640>MW_Fin,"","%MW"&(MW_Debut+640)) -> %MW1640
A20: =IF(MW_Debut+704>MW_Fin,"","%MW"&(MW_Debut+704)) -> %MW1704
A21: =IF(MW_Debut+768>MW_Fin,"","%MW"&(MW_Debut+768)) -> %MW1768
A22: =IF(MW_Debut+832>MW_Fin,"","%MW"&(MW_Debut+832)) -> %MW1832
A23: =IF(MW_Debut+896>MW_Fin,"","%MW"&(MW_Debut+896)) -> %MW1896
A24: =IF(MW_Debut+960>MW_Fin,"","%MW"&(MW_Debut+960)) -> %MW1960
A25: =IF(MW_Debut+1024>MW_Fin,"","%MW"&(MW_Debut+1024))
A26: =IF(MW_Debut+1088>MW_Fin,"","%MW"&(MW_Debut+1088))
A27: =IF(MW_Debut+1152>MW_Fin,"","%MW"&(MW_Debut+1152))
A28: =IF(MW_Debut+1216>MW_Fin,"","%MW"&(MW_Debut+1216))
A29: =IF(MW_Debut+1280>MW_Fin,"","%MW"&(MW_Debut+1280))
A30: =IF(MW_Debut+1344>MW_Fin,"","%MW"&(MW_Debut+1344))
A31: =IF(MW_Debut+1408>MW_Fin,"","%MW"&(MW_Debut+1408))
A32: =IF(MW_Debut+1472>MW_Fin,"","%MW"&(MW_Debut+1472))
A33: =IF(MW_Debut+1536>MW_Fin,"","%MW"&(MW_Debut+1536))
A34: =IF(MW_Debut+1600>MW_Fin,"","%MW"&(MW_Debut+1600))
A35: =IF(MW_Debut+1664>MW_Fin,"","%MW"&(MW_Debut+1664))
A36: =IF(MW_Debut+1728>MW_Fin,"","%MW"&(MW_Debut+1728))
A37: =IF(MW_Debut+1792>MW_Fin,"","%MW"&(MW_Debut+1792))
A38: =IF(MW_Debut+1856>MW_Fin,"","%MW"&(MW_Debut+1856))
A39: =IF(MW_Debut+1920>MW_Fin,"","%MW"&(MW_Debut+1920))
A40: =IF(MW_Debut+1984>MW_Fin,"","%MW"&(MW_Debut+1984))
A41: =IF(MW_Debut+2048>MW_Fin,"","%MW"&(MW_Debut+2048))
A42: =IF(MW_Debut+2112>MW_Fin,"","%MW"&(MW_Debut+2112))
A43: =IF(MW_Debut+2176>MW_Fin,"","%MW"&(MW_Debut+2176))
A44: =IF(MW_Debut+2240>MW_Fin,"","%MW"&(MW_Debut+2240))
...

Sheet Memoire MX
A1: CARTOGRAPHIE MEMOIRE %MX
A2: Une case par adresse, a partir de la plage declaree dans Config. Bleu : mot entier. Vert : des bits. Rouge : conflit.
A3: Affaire | B3: 2024_06_264 | D3: Client | E3: ALI
A4: Indice | B4: A | D4: Le | E4: 18/09/2026
A9: =IF(MX_Debut+0>MX_Fin,"","%MX"&(MX_Debut+0)) -> %MX0
A10: =IF(MX_Debut+64>MX_Fin,"","%MX"&(MX_Debut+64)) -> %MX64
A11: =IF(MX_Debut+128>MX_Fin,"","%MX"&(MX_Debut+128)) -> %MX128
A12: =IF(MX_Debut+192>MX_Fin,"","%MX"&(MX_Debut+192)) -> %MX192
A13: =IF(MX_Debut+256>MX_Fin,"","%MX"&(MX_Debut+256)) -> %MX256
A14: =IF(MX_Debut+320>MX_Fin,"","%MX"&(MX_Debut+320)) -> %MX320
A15: =IF(MX_Debut+384>MX_Fin,"","%MX"&(MX_Debut+384)) -> %MX384
A16: =IF(MX_Debut+448>MX_Fin,"","%MX"&(MX_Debut+448)) -> %MX448
A17: =IF(MX_Debut+512>MX_Fin,"","%MX"&(MX_Debut+512))
A18: =IF(MX_Debut+576>MX_Fin,"","%MX"&(MX_Debut+576))
A19: =IF(MX_Debut+640>MX_Fin,"","%MX"&(MX_Debut+640))
A20: =IF(MX_Debut+704>MX_Fin,"","%MX"&(MX_Debut+704))
A21: =IF(MX_Debut+768>MX_Fin,"","%MX"&(MX_Debut+768))
A22: =IF(MX_Debut+832>MX_Fin,"","%MX"&(MX_Debut+832))
A23: =IF(MX_Debut+896>MX_Fin,"","%MX"&(MX_Debut+896))
A24: =IF(MX_Debut+960>MX_Fin,"","%MX"&(MX_Debut+960))
A25: =IF(MX_Debut+1024>MX_Fin,"","%MX"&(MX_Debut+1024))
A26: =IF(MX_Debut+1088>MX_Fin,"","%MX"&(MX_Debut+1088))
A27: =IF(MX_Debut+1152>MX_Fin,"","%MX"&(MX_Debut+1152))
A28: =IF(MX_Debut+1216>MX_Fin,"","%MX"&(MX_Debut+1216))
A29: =IF(MX_Debut+1280>MX_Fin,"","%MX"&(MX_Debut+1280))
A30: =IF(MX_Debut+1344>MX_Fin,"","%MX"&(MX_Debut+1344))
A31: =IF(MX_Debut+1408>MX_Fin,"","%MX"&(MX_Debut+1408))
A32: =IF(MX_Debut+1472>MX_Fin,"","%MX"&(MX_Debut+1472))
A33: =IF(MX_Debut+1536>MX_Fin,"","%MX"&(MX_Debut+1536))
A34: =IF(MX_Debut+1600>MX_Fin,"","%MX"&(MX_Debut+1600))
A35: =IF(MX_Debut+1664>MX_Fin,"","%MX"&(MX_Debut+1664))
A36: =IF(MX_Debut+1728>MX_Fin,"","%MX"&(MX_Debut+1728))
A37: =IF(MX_Debut+1792>MX_Fin,"","%MX"&(MX_Debut+1792))
A38: =IF(MX_Debut+1856>MX_Fin,"","%MX"&(MX_Debut+1856))
A39: =IF(MX_Debut+1920>MX_Fin,"","%MX"&(MX_Debut+1920))
A40: =IF(MX_Debut+1984>MX_Fin,"","%MX"&(MX_Debut+1984))
A41: =IF(MX_Debut+2048>MX_Fin,"","%MX"&(MX_Debut+2048))
A42: =IF(MX_Debut+2112>MX_Fin,"","%MX"&(MX_Debut+2112))
A43: =IF(MX_Debut+2176>MX_Fin,"","%MX"&(MX_Debut+2176))
A44: =IF(MX_Debut+2240>MX_Fin,"","%MX"&(MX_Debut+2240))
...

Sheet ST genere
A1: (* Ecrit par le bouton Generer le ST. *)

Sheet _ASSISTANT

Sheet _ETAT
A1: VERSION | B1: 2
A2: CAT_DATE
A3: VOIES_DATE
A4: REPORTS_DATE
A5: MEM_DATE
A6: CONFLITS | B6: 0
